Workbook
Name Slicer_Delivery_Status: #N/A
Name Slicer_Months__Actual_Delivery_Date: #N/A
Name Slicer_Shipping_Mode: #N/A
Name Slicer_Supplier_Name: #N/A

Sheet Supplier Performance Dashboard

Sheet LeadTime Reliability Dashboard

Sheet Quality and Defect Dashboard

Sheet Procuremt & Invoice Inaccuracy

Sheet Supplier Risk & Segmentation

Sheet Sheet1

Sheet LeadTime Reliability Dashboard3

Sheet Pivot
G1: 8 suppliers with highest rating of 6
A2: KeyMetrics | G2: Abidjan Chemical Supply | H2: Mombasa Electricals | I2: Addis Fabric Works | J2: Sahara Packaging | K2: Nile Textiles Co. | L2: Kano Industrial Traders | M2: Primesteel Limited | N2: Mombasa Electricals | O2: Abidjan Chemical Supply | P2: Primesteel Limited, Kigali Precision Tools, Kentech Components, Lagos Plastics & Resin
A3: Count of Order_ID | B3: Sum of Order_Quantity | C3: Average Supplier Rating | D3: Average of Calculated_Lead_Time_Variance_Days | E3: Average of Defect_Rate | F3: 5 spplier with -1 lowest rating | G3: Primesteel Limited, Kigali Precision Tools, Kentech Components, Lagos Plastics & Resin | O3: Mombasa Electricals
A4: 1000 | B4: 548375 | C4: 2.9623 | D4: 2.069 | E4: 0.0252425 | O4: Addis Fabric Works | S4: whether shipping mode is influencing the delivery
F5: I am interested in knowing the % of supply accepted across supplier and the supplier with least and highest acceptance rate | O5: Sahara Packaging | S5: whether carrier is influencing the delivery
A6: =18195/B4 -> 0.03317985 | B6: 3.32% o total order is defective | J6: Abidjan had the highrest defective rate of 16% | O6: Nile Textiles Co.
O7: Kano Industrial Traders
A8: KeyMetrics2 | E8: 8 suppliers | G8: sahara | H8: cassablanca | J8: Abidjan Chemical Supply | O8: Primesteel Limited
A9: Count of Order_ID | B9: Sum of Order_Quantity | C9: Average Supplier Rating | D9: Min of Supplier_Rating | E9: Max of Supplier_Rating | F9: Average of Calculated_Lead_Time_Variance_Days | G9: Max of Calculated_Lead_Time_Variance_Days | H9: Min of Calculated_Lead_Time_Variance_Days | I9: Average of Defect_Rate | J9: Max of Defect_Rate | K9: Min of Defect_Rate | O9: Mombasa Electricals
A10: 1000 | B10: 548375 | C10: 2.9623 | D10: -1 | E10: 6 | F10: 2.069 | G10: 23 | H10: -16 | I10: 0.0252425 | J10: 0.16 | K10: 0
A13: Analysis of Count of Delivery as per delivery Status by Supplier - It is better to use Quantity rather than count | J13: vstack / xlookup
A14: Count of Delivery_Status | B14: Delivery_Status
A15: Supplier_Name | B15: Delivered Early | C15: On Time | D15: Delayed | E15: Late | F15: Very Late | G15: Severely Delayed | H15: Invalid Lead Time | I15: Grand Total | J15: Delivered Early | K15: On-Tme Deliver Rate | L15: Supplier_Name | M15: On-Tme Deliver Rate
A16: Dar | B16: 5 | C16: 22 | D16: 3 | E16: 14 | F16: 5 | G16: 6 | I16: 55 | J16: =IFERROR($B16/$I16,"") -> 0.090909091 | K16: =IFERROR($C16/$I16,"") -> 0.4 | L16: Dar Machinery Parts | M16: =J16+K16 -> 0.49090909
A17: Mombasa | B17: 10 | C17: 16 | D17: 4 | E17: 14 | F17: 9 | G17: 14 | I17: 67 | J17: =IFERROR($B17/$I17,"") -> 0.14925373 | K17: =IFERROR($C17/$I17,"") -> 0.23880597 | L17: Nile Textiles Co. | M17: =J17+K17 -> 0.3880597
A18: Kano | B18: 4 | C18: 16 | D18: 5 | E18: 25 | F18: 3 | G18: 8 | H18: 3 | I18: 64 | J18: =IFERROR($B18/$I18,"") -> 0.0625 | K18: =IFERROR($C18/$I18,"") -> 0.25 | L18: Kentech Components | M18: =J18+K18 -> 0.3125
A19: Kampala | B19: 8 | C19: 18 | D19: 4 | E19: 27 | F19: 10 | G19: 8 | H19: 2 | I19: 77 | J19: =IFERROR($B19/$I19,"") -> 0.1038961 | K19: =IFERROR($C19/$I19,"") -> 0.23376623 | L19: Abidjan Chemical Supply | M19: =J19+K19 -> 0.33766234
A20: Kigali | B20: 7 | C20: 17 | D20: 2 | E20: 22 | F20: 15 | G20: 9 | I20: 72 | J20: =IFERROR($B20/$I20,"") -> 0.097222222 | K20: =IFERROR($C20/$I20,"") -> 0.23611111 | L20: Addis Fabric Works | M20: =J20+K20 -> 0.33333333
A21: Nile | B21: 4 | C21: 23 | D21: 4 | E21: 12 | F21: 8 | G21: 10 | I21: 61 | J21: =IFERROR($B21/$I21,"") -> 0.06557377 | K21: =IFERROR($C21/$I21,"") -> 0.37704918 | L21: Cape Logistics Supplies | M21: =J21+K21 -> 0.44262295
A22: Kentech | B22: 5 | C22: 25 | D22: 6 | E22: 20 | F22: 9 | G22: 11 | I22: 76 | J22: =IFERROR($B22/$I22,"") -> 0.065789474 | K22: =IFERROR($C22/$I22,"") -> 0.32894737 | L22: Sahara Packaging | M22: =J22+K22 -> 0.39473684
A23: Cape | B23: 7 | C23: 18 | D23: 5 | E23: 17 | F23: 10 | G23: 8 | I23: 65 | J23: =IFERROR($B23/$I23,"") -> 0.10769231 | K23: =IFERROR($C23/$I23,"") -> 0.27692308 | L23: Kano Industrial Traders | M23: =J23+K23 -> 0.38461538
A24: Casablanca | B24: 7 | C24: 10 | D24: 6 | E24: 17 | F24: 6 | G24: 7 | I24: 53 | J24: =IFERROR($B24/$I24,"") -> 0.13207547 | K24: =IFERROR($C24/$I24,"") -> 0.18867925 | L24: Accra Agro Inputs | M24: =J24+K24 -> 0.32075472
A25: Sahara | B25: 8 | C25: 20 | D25: 4 | E25: 25 | F25: 5 | G25: 12 | H25: 4 | I25: 78 | J25: =IFERROR($B25/$I25,"") -> 0.1025641 | K25: =IFERROR($C25/$I25,"") -> 0.25641026 | L25: Mombasa Electricals | M25: =J25+K25 -> 0.35897436
A26: Primesteel | B26: 7 | C26: 11 | D26: 7 | E26: 16 | F26: 6 | G26: 11 | H26: 1 | I26: 59 | J26: =IFERROR($B26/$I26,"") -> 0.11864407 | K26: =IFERROR($C26/$I26,"") -> 0.18644068 | L26: Kigali Precision Tools | M26: =J26+K26 -> 0.30508475
A27: AccraAI | B27: 6 | C27: 17 | D27: 2 | E27: 22 | F27: 9 | G27: 12 | H27: 1 | I27: 69 | J27: =IFERROR($B27/$I27,"") -> 0.086956522 | K27: =IFERROR($C27/$I27,"") -> 0.24637681 | L27: Kampala Packaging Hub | M27: =J27+K27 -> 0.33333333
A28: LagosPR | B28: 11 | C28: 15 | D28: 8 | E28: 13 | F28: 5 | G28: 12 | H28: 3 | I28: 67 | J28: =IFERROR($B28/$I28,"") -> 0.1641791 | K28: =IFERROR($C28/$I28,"") -> 0.2238806 | L28: Lagos Plastics & Resin | M28: =J28+K28 -> 0.3880597
A29: AddisFW | B29: 7 | C29: 21 | D29: 3 | E29: 20 | F29: 9 | G29: 14 | I29: 74 | J29: =IFERROR($B29/$I29,"") -> 0.094594595 | K29: =IFERROR($C29/$I29,"") -> 0.28378378 | L29: Casablanca Components | M29: =J29+K29 -> 0.37837838
A30: AbidjanCS | B30: 8 | C30: 19 | D30: 4 | E30: 14 | F30: 11 | G30: 7 | I30: 63 | J30: =IFERROR($B30/$I30,"") -> 0.12698413 | K30: =IFERROR($C30/$I30,"") -> 0.3015873 | L30: Primesteel Limited | M30: =J30+K30 -> 0.42857143
A31: Grand Total | B31: 104 | C31: 268 | D31: 67 | E31: 278 | F31: 120 | G31: 149 | H31: 14 | I31: 1000 | J31: =AVERAGE(J16:J30) -> 0.10458898 | K31: =AVERAGE(K16:K30) -> 0.26858411
A35: DeliveryStatusbyCarrier
A37: Count of Delivery_Status | B37: Delivery_Status
A38: Carrier | B38: Delivered Early | C38: On Time | D38: Delayed | E38: Late | F38: Very Late | G38: Severely Delayed | H38: Invalid Lead Time | I38: Grand Total
A39: Bollore Logistics | B39: 20 | C39: 34 | D39: 11 | E39: 33 | F39: 15 | G39: 18 | H39: 5 | I39: 136
A40: DHL | B40: 20 | C40: 45 | D40: 8 | E40: 42 | F40: 10 | G40: 15 | H40: 2 | I40: 142
A41: GIG Logistics | B41: 11 | C41: 34 | D41: 7 | E41: 30 | F41: 19 | G41: 17 | H41: 2 | I41: 120
A42: Kuehne+Nagel | B42: 6 | C42: 21 | D42: 15 | E42: 23 | F42: 11 | G42: 21 | I42: 97
A43: Local Truck Partner | B43: 14 | C43: 28 | D43: 4 | E43: 38 | F43: 16 | G43: 18 | H43: 2 | I43: 120
A44: Maersk | B44: 5 | C44: 40 | D44: 9 | E44: 31 | F44: 25 | G44: 23 | I44: 133
A45: No Carrier Listed | B45: 28 | C45: 66 | D45: 13 | E45: 81 | F45: 24 | G45: 37 | H45: 3 | I45: 252
A46: Grand Total | B46: 104 | C46: 268 | D46: 67 | E46: 278 | F46: 120 | G46: 149 | H46: 14 | I46: 1000
...

Sheet Pivot Table Analysis
A2: KeyMetrics
A3: Count of Order_ID | B3: Sum of Order_Quantity | C3: Average Supplier Rating | D3: Average of Calculated_Lead_Time_Variance_Days | E3: Average of Defect_Rate | F3: 5 suppliers that had-1 lowest rating | G3: Primesteel Limited, Kigali Precision Tools, Kentech Components, Lagos Plastics & Resin
A4: 1000 | B4: 548375 | C4: 2.9623 | D4: 2.069 | E4: 0.0252425
A6: =18195/B4 -> 0.03317985 | B6: 3.32% o total order is defective | J6: Abidjan had the highrest defective rate of 16%
A8: KeyMetrics2 | E8: 8 suppliers | G8: sahara | H8: cassablanca | J8: Abidjan Chemical Supply
A9: Count of Order_ID | B9: Sum of Order_Quantity | C9: Average Supplier Rating | D9: Min of Supplier_Rating | E9: Max of Supplier_Rating | F9: Average of Calculated_Lead_Time_Variance_Days | G9: Max of Calculated_Lead_Time_Variance_Days | H9: Min of Calculated_Lead_Time_Variance_Days | I9: Average of Defect_Rate | J9: Max of Defect_Rate | K9: Min of Defect_Rate
A10: 1000 | B10: 548375 | C10: 2.9623 | D10: -1 | E10: 6 | F10: 2.069 | G10: 23 | H10: -16 | I10: 0.0252425 | J10: 0.16 | K10: 0
A13: Analysis of Count of Delivery as per delivery Status by Supplier - It is better to use Quantity rather than count
A14: Count of Delivery_Status | B14: Delivery_Status
A15: Supplier_Name | B15: Delivered Early | C15: On Time | D15: Delayed | E15: Late | F15: Very Late | G15: Severely Delayed | H15: Invalid Lead Time | I15: Grand Total | J15: Delivered Early | K15: On-Tme Deliver Rate | L15: Supplier_Name | M15: On-Tme Deliver Rate
A16: Dar | B16: 5 | C16: 22 | D16: 3 | E16: 14 | F16: 5 | G16: 6 | I16: 55 | J16: =$B16/$I16 -> 0.090909091 | K16: =$C16/$I16 -> 0.4 | L16: Dar Machinery Parts | M16: =J16+K16 -> 0.49090909
A17: Mombasa | B17: 10 | C17: 16 | D17: 4 | E17: 14 | F17: 9 | G17: 14 | I17: 67 | J17: =$B17/$I17 -> 0.14925373 | K17: =$C17/$I17 -> 0.23880597 | L17: Nile Textiles Co. | M17: =J17+K17 -> 0.3880597
A18: Kano | B18: 4 | C18: 16 | D18: 5 | E18: 25 | F18: 3 | G18: 8 | H18: 3 | I18: 64 | J18: =$B18/$I18 -> 0.0625 | K18: =$C18/$I18 -> 0.25 | L18: Kentech Components | M18: =J18+K18 -> 0.3125
A19: Kampala | B19: 8 | C19: 18 | D19: 4 | E19: 27 | F19: 10 | G19: 8 | H19: 2 | I19: 77 | J19: =$B19/$I19 -> 0.1038961 | K19: =$C19/$I19 -> 0.23376623 | L19: Abidjan Chemical Supply | M19: =J19+K19 -> 0.33766234
A20: Kigali | B20: 7 | C20: 17 | D20: 2 | E20: 22 | F20: 15 | G20: 9 | I20: 72 | J20: =$B20/$I20 -> 0.097222222 | K20: =$C20/$I20 -> 0.23611111 | L20: Addis Fabric Works | M20: =J20+K20 -> 0.33333333
A21: Nile | B21: 4 | C21: 23 | D21: 4 | E21: 12 | F21: 8 | G21: 10 | I21: 61 | J21: =$B21/$I21 -> 0.06557377 | K21: =$C21/$I21 -> 0.37704918 | L21: Cape Logistics Supplies | M21: =J21+K21 -> 0.44262295
A22: Kentech | B22: 5 | C22: 25 | D22: 6 | E22: 20 | F22: 9 | G22: 11 | I22: 76 | J22: =$B22/$I22 -> 0.065789474 | K22: =$C22/$I22 -> 0.32894737 | L22: Sahara Packaging | M22: =J22+K22 -> 0.39473684
A23: Cape | B23: 7 | C23: 18 | D23: 5 | E23: 17 | F23: 10 | G23: 8 | I23: 65 | J23: =$B23/$I23 -> 0.10769231 | K23: =$C23/$I23 -> 0.27692308 | L23: Kano Industrial Traders | M23: =J23+K23 -> 0.38461538
A24: Casablanca | B24: 7 | C24: 10 | D24: 6 | E24: 17 | F24: 6 | G24: 7 | I24: 53 | J24: =$B24/$I24 -> 0.13207547 | K24: =$C24/$I24 -> 0.18867925 | L24: Accra Agro Inputs | M24: =J24+K24 -> 0.32075472
A25: Sahara | B25: 8 | C25: 20 | D25: 4 | E25: 25 | F25: 5 | G25: 12 | H25: 4 | I25: 78 | J25: =$B25/$I25 -> 0.1025641 | K25: =$C25/$I25 -> 0.25641026 | L25: Mombasa Electricals | M25: =J25+K25 -> 0.35897436
A26: Primesteel | B26: 7 | C26: 11 | D26: 7 | E26: 16 | F26: 6 | G26: 11 | H26: 1 | I26: 59 | J26: =$B26/$I26 -> 0.11864407 | K26: =$C26/$I26 -> 0.18644068 | L26: Kigali Precision Tools | M26: =J26+K26 -> 0.30508475
A27: AccraAI | B27: 6 | C27: 17 | D27: 2 | E27: 22 | F27: 9 | G27: 12 | H27: 1 | I27: 69 | J27: =$B27/$I27 -> 0.086956522 | K27: =$C27/$I27 -> 0.24637681 | L27: Kampala Packaging Hub | M27: =J27+K27 -> 0.33333333
A28: LagosPR | B28: 11 | C28: 15 | D28: 8 | E28: 13 | F28: 5 | G28: 12 | H28: 3 | I28: 67 | J28: =$B28/$I28 -> 0.1641791 | K28: =$C28/$I28 -> 0.2238806 | L28: Lagos Plastics & Resin | M28: =J28+K28 -> 0.3880597
A29: AddisFW | B29: 7 | C29: 21 | D29: 3 | E29: 20 | F29: 9 | G29: 14 | I29: 74 | J29: =$B29/$I29 -> 0.094594595 | K29: =$C29/$I29 -> 0.28378378 | L29: Casablanca Components | M29: =J29+K29 -> 0.37837838
A30: AbidjanCS | B30: 8 | C30: 19 | D30: 4 | E30: 14 | F30: 11 | G30: 7 | I30: 63 | J30: =$B30/$I30 -> 0.12698413 | K30: =$C30/$I30 -> 0.3015873 | L30: Primesteel Limited | M30: =J30+K30 -> 0.42857143
A31: Grand Total | B31: 104 | C31: 268 | D31: 67 | E31: 278 | F31: 120 | G31: 149 | H31: 14 | I31: 1000 | J31: =$B31/$I31 -> 0.104 | K31: =$C31/$I31 -> 0.268
A35: DeliveryStatusbyCarrier
A37: Count of Delivery_Status | B37: Delivery_Status
A38: Carrier | B38: Delivered Early | C38: On Time | D38: Delayed | E38: Late | F38: Very Late | G38: Severely Delayed | H38: Invalid Lead Time | I38: Grand Total
A39: Bollore Logistics | B39: 20 | C39: 34 | D39: 11 | E39: 33 | F39: 15 | G39: 18 | H39: 5 | I39: 136
A40: DHL | B40: 20 | C40: 45 | D40: 8 | E40: 42 | F40: 10 | G40: 15 | H40: 2 | I40: 142
A41: GIG Logistics | B41: 11 | C41: 34 | D41: 7 | E41: 30 | F41: 19 | G41: 17 | H41: 2 | I41: 120
A42: Kuehne+Nagel | B42: 6 | C42: 21 | D42: 15 | E42: 23 | F42: 11 | G42: 21 | I42: 97
A43: Local Truck Partner | B43: 14 | C43: 28 | D43: 4 | E43: 38 | F43: 16 | G43: 18 | H43: 2 | I43: 120
A44: Maersk | B44: 5 | C44: 40 | D44: 9 | E44: 31 | F44: 25 | G44: 23 | I44: 133
A45: No Carrier Listed | B45: 28 | C45: 66 | D45: 13 | E45: 81 | F45: 24 | G45: 37 | H45: 3 | I45: 252
A46: Grand Total | B46: 104 | C46: 268 | D46: 67 | E46: 278 | F46: 120 | G46: 149 | H46: 14 | I46: 1000
A49: DefectRatebyCarrier
A50: The average defect rate of all the carrier is below 3% with Bollore logistics having the minimum of 2.31% , while Kuehne+Nagel had the maximum of 2.81%
A51: Carrier | B51: Average of Defect_Rate
...

Sheet Cleaned_Data
A1: PO_ID | B1: Order_ID | C1: Order Date | D1: Expected Delivery_Date | E1: Actual_Delivery_Date | F1: Supplier_ID | G1: Supplier_Name | H1: Supplier_Country | I1: Buyer_Location | J1: Product_Category | K1: SKU | L1: Item_Description | M1: Unit_Cost | N1: Currency | O1: Dollar Equivalent | P1: Unit_Cost in $ | Q1: Order_Quantity | R1: Ordered_Value | S1: Calculated_Order_Value | T1: Ordered_Value in $ | U1: Defective_Units | V1: Defect_Rate | W1: Lead_Time_Days | X1: Calculated_Lead_Time2 | Y1: Promised_Lead_Time_Days | Z1: Calculated_Expected_Lead_Time | AA1: Calculated_Lead_Time_Variance_Days | AB1: Lead_Time_Variance_Days | AC1: Delivery_Status | AD1: Quality_Status | AE1: Invoice_Status | AF1: Payment_Terms | AG1: Shipping_Mode | AH1: Carrier | AI1: Incoterm | AJ1: Rejection_Reason | AK1: Supplier_Rating | AL1: Data_Source | AM1: Data_Quality_Notes
A2: PO-2026-00001 | B2: ORD-585176 | C2: 46081 | D2: 46101 | E2: 46111 | F2: SUP-007 | G2: Dar | H2: Tanzania | I2: Lagos DC | J2: Machinery Parts | K2: SKU-MAC-466 | L2: Hydraulic Hose | M2: 353.52 | N2: KES | O2: =_xlfn.XLOOKUP(Supplier_Perf_Table[[#This Row],[Currency]],'Comments 2'!$C$4:$C$16,'Comments 2'!$D$4:$D$16) -> 0.0077 | P2: =IFERROR(Supplier_Perf_Table[[#This Row],[Unit_Cost]]*Supplier_Perf_Table[[#This Row],[Dollar Equivalent]],"") -> 2.722104 | Q2: 1500 | R2: 530280 | S2: =Supplier_Perf_Table[[#This Row],[Unit_Cost]]*Supplier_Perf_Table[[#This Row],[Order_Quantity]] -> 530280 | T2: =IFERROR(Supplier_Perf_Table[[#This Row],[Dollar Equivalent]]*Supplier_Perf_Table[[#This Row],[Ordered_Value]],"") -> 4083.156 | U2: 41 | V2: 0.0273 | X2: =IFERROR(Supplier_Perf_Table[[#This Row],[Actual_Delivery_Date]]-Supplier_Perf_Table[[#This Row],[Order Date]],"") -> 30 | Y2: 20 | Z2: =IFERROR(Supplier_Perf_Table[[#This Row],[Expected Delivery_Date]]-Supplier_Perf_Table[[#This Row],[Order Date]],"") -> 20 | AA2: =Supplier_Perf_Table[[#This Row],[Calculated_Lead_Time2]]-Supplier_Perf_Table[[#This Row],[Calculated_Expected_Lead_Time]] -> 10 | AB2: 10 | AC2: Severely Delayed | AD2: Accepted | AE2: Pending | AF2: Net 45 | AG2: Sea | AH2: No Carrier Listed | AI2: DDP | AJ2: N/A | AK2: 2.2 | AL2: Supplier Portal | AM2: Late delivery
A3: PO-2026-00001 | B3: ORD-317662 | C3: 46066 | D3: 46079 | E3: 46082 | F3: SUP-009 | G3: Mombasa | H3: Kenya | I3: Kampala Warehouse | J3: Electronics | K3: SKU-ELE-426 | L3: Power Adapter | M3: 24.24 | N3: ZAR | O3: =_xlfn.XLOOKUP(Supplier_Perf_Table[[#This Row],[Currency]],'Comments 2'!$C$4:$C$16,'Comments 2'!$D$4:$D$16) -> 0.061 | P3: =IFERROR(Supplier_Perf_Table[[#This Row],[Unit_Cost]]*Supplier_Perf_Table[[#This Row],[Dollar Equivalent]],"") -> 1.47864 | Q3: 100 | R3: 2424 | S3: =Supplier_Perf_Table[[#This Row],[Unit_Cost]]*Supplier_Perf_Table[[#This Row],[Order_Quantity]] -> 2424 | T3: =IFERROR(Supplier_Perf_Table[[#This Row],[Dollar Equivalent]]*Supplier_Perf_Table[[#This Row],[Ordered_Value]],"") -> 147.864 | U3: 0 | V3: 0 | W3: 16 | X3: =IFERROR(Supplier_Perf_Table[[#This Row],[Actual_Delivery_Date]]-Supplier_Perf_Table[[#This Row],[Order Date]],"") -> 16 | Y3: 13 | Z3: =IFERROR(Supplier_Perf_Table[[#This Row],[Expected Delivery_Date]]-Supplier_Perf_Table[[#This Row],[Order Date]],"") -> 13 | AA3: =Supplier_Perf_Table[[#This Row],[Calculated_Lead_Time2]]-Supplier_Perf_Table[[#This Row],[Calculated_Expected_Lead_Time]] -> 3 | AB3: 3 | AC3: Late | AD3: Accepted | AE3: Pending | AF3: Not Stated | AG3: Rail | AH3: Kuehne+Nagel | AI3: EXW | AJ3: N/A | AK3: 5 | AL3: Legacy CSV | AM3: Late delivery
A4: PO-2026-00003 | B4: ORD-541564 | C4: 46151 | D4: 46160 | E4: 46165 | F4: SUP-014 | G4: Kano | H4: Nigeria | I4: Accra Hub | J4: Industrial Supplies | K4: SKU-IND-171 | L4: Filter Cartridge | M4: 690.99 | N4: USD | O4: =_xlfn.XLOOKUP(Supplier_Perf_Table[[#This Row],[Currency]],'Comments 2'!$C$4:$C$16,'Comments 2'!$D$4:$D$16) -> 1 | P4: =IFERROR(Supplier_Perf_Table[[#This Row],[Unit_Cost]]*Supplier_Perf_Table[[#This Row],[Dollar Equivalent]],"") -> 690.99 | Q4: 300 | R4: 207297 | S4: =Supplier_Perf_Table[[#This Row],[Unit_Cost]]*Supplier_Perf_Table[[#This Row],[Order_Quantity]] -> 207297 | T4: =IFERROR(Supplier_Perf_Table[[#This Row],[Dollar Equivalent]]*Supplier_Perf_Table[[#This Row],[Ordered_Value]],"") -> 207297 | U4: 5 | V4: 0.0167 | W4: 14 | X4: =IFERROR(Supplier_Perf_Table[[#This Row],[Actual_Delivery_Date]]-Supplier_Perf_Table[[#This Row],[Order Date]],"") -> 14 | Y4: 9 | Z4: =IFERROR(Supplier_Perf_Table[[#This Row],[Expected Delivery_Date]]-Supplier_Perf_Table[[#This Row],[Order Date]],"") -> 9 | AA4: =Supplier_Perf_Table[[#This Row],[Calculated_Lead_Time2]]-Supplier_Perf_Table[[#This Row],[Calculated_Expected_Lead_Time]] -> 5 | AB4: 5 | AC4: Late | AD4: Accepted | AE4: Matched | AF4: COD | AG4: Road | AH4: No Carrier Listed | AI4: DDP | AJ4: N/A | AK4: 4.9 | AL4: Supplier Portal | AM4: Late delivery
A5: PO-2026-00004 | B5: ORD-635943 | C5: 46127 | D5: 46139 | E5: 46147 | F5: SUP-015 | G5: Kampala | H5: Uganda | I5: Dar es Salaam Port | J5: Textiles | K5: SKU-TEX-310 | L5: Polyester Roll | M5: 375.45 | N5: USD | O5: =_xlfn.XLOOKUP(Supplier_Perf_Table[[#This Row],[Currency]],'Comments 2'!$C$4:$C$16,'Comments 2'!$D$4:$D$16) -> 1 | P5: =IFERROR(Supplier_Perf_Table[[#This Row],[Unit_Cost]]*Supplier_Perf_Table[[#This Row],[Dollar Equivalent]],"") -> 375.45 | Q5: 1000 | R5: 375450 | S5: =Supplier_Perf_Table[[#This Row],[Unit_Cost]]*Supplier_Perf_Table[[#This Row],[Order_Quantity]] -> 375450 | T5: =IFERROR(Supplier_Perf_Table[[#This Row],[Dollar Equivalent]]*Supplier_Perf_Table[[#This Row],[Ordered_Value]],"") -> 375450 | U5: 49 | V5: 0.049 | W5: -5 | X5: =IFERROR(Supplier_Perf_Table[[#This Row],[Actual_Delivery_Date]]-Supplier_Perf_Table[[#This Row],[Order Date]],"") -> 20 | Y5: 12 | Z5: =IFERROR(Supplier_Perf_Table[[#This Row],[Expected Delivery_Date]]-Supplier_Perf_Table[[#This Row],[Order Date]],"") -> 12 | AA5: =Supplier_Perf_Table[[#This Row],[Calculated_Lead_Time2]]-Supplier_Perf_Table[[#This Row],[Calculated_Expected_Lead_Time]] -> 8 | AC5: Severely Delayed | AD5: Hold | AE5: Pending | AF5: COD | AG5: Sea | AH5: No Carrier Listed | AI5: DDP | AJ5: Damaged packaging | AK5: 3.3 | AL5: Email Invoice | AM5: Late delivery; Quality issue
A6: PO-2026-00005 | B6: ORD-833742 | C6: 46178 | D6: 46191 | E6: 46185 | F6: SUP-011 | G6: Kigali | H6: Rwanda | I6: Kigali Assembly | J6: Machinery Parts | K6: SKU-MAC-288 | L6: Conveyor Belt | M6: 2996.25 | N6: GHS | O6: =_xlfn.XLOOKUP(Supplier_Perf_Table[[#This Row],[Currency]],'Comments 2'!$C$4:$C$16,'Comments 2'!$D$4:$D$16) -> 0.089 | P6: =IFERROR(Supplier_Perf_Table[[#This Row],[Unit_Cost]]*Supplier_Perf_Table[[#This Row],[Dollar Equivalent]],"") -> 266.66625 | Q6: 75 | R6: 224718.75 | S6: =Supplier_Perf_Table[[#This Row],[Unit_Cost]]*Supplier_Perf_Table[[#This Row],[Order_Quantity]] -> 224718.75 | T6: =IFERROR(Supplier_Perf_Table[[#This Row],[Dollar Equivalent]]*Supplier_Perf_Table[[#This Row],[Ordered_Value]],"") -> 19999.969 | U6: 0 | V6: 0 | W6: 7 | X6: =IFERROR(Supplier_Perf_Table[[#This Row],[Actual_Delivery_Date]]-Supplier_Perf_Table[[#This Row],[Order Date]],"") -> 7 | Y6: 13 | Z6: =IFERROR(Supplier_Perf_Table[[#This Row],[Expected Delivery_Date]]-Supplier_Perf_Table[[#This Row],[Order Date]],"") -> 13 | AA6: =Supplier_Perf_Table[[#This Row],[Calculated_Lead_Time2]]-Supplier_Perf_Table[[#This Row],[Calculated_Expected_Lead_Time]] -> -6 | AB6: -6 | AC6: On Time | AD6: Accepted | AE6: Matched | AF6: Net 30 | AG6: Not Stated | AH6: Bollore Logistics | AI6: EXW | AJ6: N/A | AK6: 3.4 | AL6: Email Invoice | AM6: N/A
A7: PO-2026-00004 | B7: ORD-660938 | C7: 46149 | D7: 46163 | E7: 46160 | F7: SUP-004 | G7: Nile | H7: Egypt | I7: Abuja Plant | J7: Industrial Supplies | K7: SKU-IND-861 | L7: Safety Gloves | M7: 224.15 | N7: KES | O7: =_xlfn.XLOOKUP(Supplier_Perf_Table[[#This Row],[Currency]],'Comments 2'!$C$4:$C$16,'Comments 2'!$D$4:$D$16) -> 0.0077 | P7: =IFERROR(Supplier_Perf_Table[[#This Row],[Unit_Cost]]*Supplier_Perf_Table[[#This Row],[Dollar Equivalent]],"") -> 1.725955 | Q7: 1000 | R7: 224150 | S7: =Supplier_Perf_Table[[#This Row],[Unit_Cost]]*Supplier_Perf_Table[[#This Row],[Order_Quantity]] -> 224150 | T7: =IFERROR(Supplier_Perf_Table[[#This Row],[Dollar Equivalent]]*Supplier_Perf_Table[[#This Row],[Ordered_Value]],"") -> 1725.955 | U7: 70 | V7: 0.07 | W7: 11 | X7: =IFERROR(Supplier_Perf_Table[[#This Row],[Actual_Delivery_Date]]-Supplier_Perf_Table[[#This Row],[Order Date]],"") -> 11 | Y7: 14 | Z7: =IFERROR(Supplier_Perf_Table[[#This Row],[Expected Delivery_Date]]-Supplier_Perf_Table[[#This Row],[Order Date]],"") -> 14 | AA7: =Supplier_Perf_Table[[#This Row],[Calculated_Lead_Time2]]-Supplier_Perf_Table[[#This Row],[Calculated_Expected_Lead_Time]] -> -3 | AB7: -3 | AC7: On Time | AD7: Hold | AE7: Pending | AF7: COD | AG7: Sea | AH7: Bollore Logistics | AI7: FOB | AJ7: Missing certificate | AK7: 1.8 | AL7: Email Invoice | AM7: Quality issue
A8: PO-2026-00007 | B8: ORD-717922 | C8: 46120 | D8: 46137 | E8: 46142 | F8: SUP-002 | G8: Kentech | H8: Kenya | I8: Lagos DC | J8: Electronics | K8: SKU-ELE-698 | L8: Power Adapter | M8: 3665.29 | N8: EGP | O8: =_xlfn.XLOOKUP(Supplier_Perf_Table[[#This Row],[Currency]],'Comments 2'!$C$4:$C$16,'Comments 2'!$D$4:$D$16) -> 0.019 | P8: =IFERROR(Supplier_Perf_Table[[#This Row],[Unit_Cost]]*Supplier_Perf_Table[[#This Row],[Dollar Equivalent]],"") -> 69.64051 | Q8: 1000 | R8: 3665290 | S8: =Supplier_Perf_Table[[#This Row],[Unit_Cost]]*Supplier_Perf_Table[[#This Row],[Order_Quantity]] -> 3665290 | T8: =IFERROR(Supplier_Perf_Table[[#This Row],[Dollar Equivalent]]*Supplier_Perf_Table[[#This Row],[Ordered_Value]],"") -> 69640.51 | U8: 14 | V8: 0.014 | W8: 22 | X8: =IFERROR(Supplier_Perf_Table[[#This Row],[Actual_Delivery_Date]]-Supplier_Perf_Table[[#This Row],[Order Date]],"") -> 22 | Y8: 17 | Z8: =IFERROR(Supplier_Perf_Table[[#This Row],[Expected Delivery_Date]]-Supplier_Perf_Table[[#This Row],[Order Date]],"") -> 17 | AA8: =Supplier_Perf_Table[[#This Row],[Calculated_Lead_Time2]]-Supplier_Perf_Table[[#This Row],[Calculated_Expected_Lead_Time]] -> 5 | AB8: 5 | AC8: Severely Delayed | AD8: Accepted | AE8: Matched | AF8: Net 30 | AG8: Courier | AH8: Bollore Logistics | AI8: FOB | AJ8: N/A | AK8: 3.4 | AL8: ERP | AM8: Late delivery
A9: PO-2026-00008 | B9: ORD-198520 | C9: 46097 | D9: 46113 | E9: 46098 | F9: SUP-015 | G9: Kampala | H9: Uganda | I9: Kigali Assembly | J9: Packaging | K9: SKU-PAC-104 | L9: Corrugated Box | M9: 719.98 | N9: EGP | O9: =_xlfn.XLOOKUP(Supplier_Perf_Table[[#This Row],[Currency]],'Comments 2'!$C$4:$C$16,'Comments 2'!$D$4:$D$16) -> 0.019 | P9: =IFERROR(Supplier_Perf_Table[[#This Row],[Unit_Cost]]*Supplier_Perf_Table[[#This Row],[Dollar Equivalent]],"") -> 13.67962 | Q9: 1000 | R9: 719980 | S9: =Supplier_Perf_Table[[#This Row],[Unit_Cost]]*Supplier_Perf_Table[[#This Row],[Order_Quantity]] -> 719980 | T9: =IFERROR(Supplier_Perf_Table[[#This Row],[Dollar Equivalent]]*Supplier_Perf_Table[[#This Row],[Ordered_Value]],"") -> 13679.62 | U9: 32 | V9: 0.032 | W9: 1 | X9: =IFERROR(Supplier_Perf_Table[[#This Row],[Actual_Delivery_Date]]-Supplier_Perf_Table[[#This Row],[Order Date]],"") -> 1 | Y9: 16 | Z9: =IFERROR(Supplier_Perf_Table[[#This Row],[Expected Delivery_Date]]-Supplier_Perf_Table[[#This Row],[Order Date]],"") -> 16 | AA9: =Supplier_Perf_Table[[#This Row],[Calculated_Lead_Time2]]-Supplier_Perf_Table[[#This Row],[Calculated_Expected_Lead_Time]] -> -15 | AB9: -15 | AC9: On Time | AD9: Accepted | AE9: Pending | AF9: Not Stated | AG9: Rail | AH9: Bollore Logistics | AI9: FOB | AJ9: N/A | AK9: 2.9 | AL9: API Feed | AM9: N/A
A10: PO-2026-00009 | B10: ORD-346142 | C10: 46069 | D10: 46087 | E10: 46085 | F10: SUP-005 | G10: Cape | H10: South Africa | I10: Nairobi DC | J10: Industrial Supplies | K10: SKU-IND-637 | L10: Lubricant Drum | M10: 200.24 | N10: USD | O10: =_xlfn.XLOOKUP(Supplier_Perf_Table[[#This Row],[Currency]],'Comments 2'!$C$4:$C$16,'Comments 2'!$D$4:$D$16) -> 1 | P10: =IFERROR(Supplier_Perf_Table[[#This Row],[Unit_Cost]]*Supplier_Perf_Table[[#This Row],[Dollar Equivalent]],"") -> 200.24 | Q10: 500 | R10: 100120 | S10: =Supplier_Perf_Table[[#This Row],[Unit_Cost]]*Supplier_Perf_Table[[#This Row],[Order_Quantity]] -> 100120 | T10: =IFERROR(Supplier_Perf_Table[[#This Row],[Dollar Equivalent]]*Supplier_Perf_Table[[#This Row],[Ordered_Value]],"") -> 100120 | U10: 13 | V10: 0.026 | W10: 16 | X10: =IFERROR(Supplier_Perf_Table[[#This Row],[Actual_Delivery_Date]]-Supplier_Perf_Table[[#This Row],[Order Date]],"") -> 16 | Y10: 18 | Z10: =IFERROR(Supplier_Perf_Table[[#This Row],[Expected Delivery_Date]]-Supplier_Perf_Table[[#This Row],[Order Date]],"") -> 18 | AA10: =Supplier_Perf_Table[[#This Row],[Calculated_Lead_Time2]]-Supplier_Perf_Table[[#This Row],[Calculated_Expected_Lead_Time]] -> -2 | AB10: -2 | AC10: On Time | AD10: Accepted | AE10: Pending | AF10: COD | AG10: Sea | AH10: No Carrier Listed | AI10: DDP | AJ10: N/A | AK10: 4.6 | AL10: Email Invoice | AM10: N/A
A11: PO-2026-00010 | B11: ORD-493495 | C11: 46167 | D11: 46180 | E11: 46180 | F11: SUP-002 | G11: Kentech | H11: Kenya | I11: Nairobi DC | J11: Electronics | K11: SKU-ELE-651 | L11: Control Board | M11: 3659.46 | N11: KES | O11: =_xlfn.XLOOKUP(Supplier_Perf_Table[[#This Row],[Currency]],'Comments 2'!$C$4:$C$16,'Comments 2'!$D$4:$D$16) -> 0.0077 | P11: =IFERROR(Supplier_Perf_Table[[#This Row],[Unit_Cost]]*Supplier_Perf_Table[[#This Row],[Dollar Equivalent]],"") -> 28.177842 | Q11: 300 | R11: 1097838 | S11: =Supplier_Perf_Table[[#This Row],[Unit_Cost]]*Supplier_Perf_Table[[#This Row],[Order_Quantity]] -> 1097838 | T11: =IFERROR(Supplier_Perf_Table[[#This Row],[Dollar Equivalent]]*Supplier_Perf_Table[[#This Row],[Ordered_Value]],"") -> 8453.3526 | U11: 7 | V11: 0.0233 | W11: 13 | X11: =IFERROR(Supplier_Perf_Table[[#This Row],[Actual_Delivery_Date]]-Supplier_Perf_Table[[#This Row],[Order Date]],"") -> 13 | Y11: 13 | Z11: =IFERROR(Supplier_Perf_Table[[#This Row],[Expected Delivery_Date]]-Supplier_Perf_Table[[#This Row],[Order Date]],"") -> 13 | AA11: =Supplier_Perf_Table[[#This Row],[Calculated_Lead_Time2]]-Supplier_Perf_Table[[#This Row],[Calculated_Expected_Lead_Time]] -> 0 | AB11: 0 | AC11: On Time | AD11: Accepted | AE11: Disputed | AF11: Not Stated | AG11: Air | AH11: DHL | AI11: EXW | AJ11: N/A | AK11: 2.2 | AL11: Supplier Portal | AM11: Invoice issue
A12: PO-2026-00011 | B12: ORD-901706 | C12: 46041 | D12: 46057 | E12: 46058 | F12: SUP-004 | G12: Nile | H12: Egypt | I12: Dar es Salaam Port | J12: Textiles | K12: SKU-TEX-536 | L12: Polyester Roll | M12: 361.63 | N12: USD | O12: =_xlfn.XLOOKUP(Supplier_Perf_Table[[#This Row],[Currency]],'Comments 2'!$C$4:$C$16,'Comments 2'!$D$4:$D$16) -> 1 | P12: =IFERROR(Supplier_Perf_Table[[#This Row],[Unit_Cost]]*Supplier_Perf_Table[[#This Row],[Dollar Equivalent]],"") -> 361.63 | Q12: 2000 | R12: 723260 | S12: =Supplier_Perf_Table[[#This Row],[Unit_Cost]]*Supplier_Perf_Table[[#This Row],[Order_Quantity]] -> 723260 | T12: =IFERROR(Supplier_Perf_Table[[#This Row],[Dollar Equivalent]]*Supplier_Perf_Table[[#This Row],[Ordered_Value]],"") -> 723260 | U12: 102 | V12: 0.051 | W12: 17 | X12: =IFERROR(Supplier_Perf_Table[[#This Row],[Actual_Delivery_Date]]-Supplier_Perf_Table[[#This Row],[Order Date]],"") -> 17 | Y12: 16 | Z12: =IFERROR(Supplier_Perf_Table[[#This Row],[Expected Delivery_Date]]-Supplier_Perf_Table[[#This Row],[Order Date]],"") -> 16 | AA12: =Supplier_Perf_Table[[#This Row],[Calculated_Lead_Time2]]-Supplier_Perf_Table[[#This Row],[Calculated_Expected_Lead_Time]] -> 1 | AB12: 1 | AC12: Late | AD12: Hold | AE12: Pending | AF12: Net 30 | AG12: Rail | AH12: Maersk | AI12: CIF | AJ12: Missing certificate | AK12: 3 | AL12: Manual Excel Upload | AM12: Late delivery; Quality issue
A13: PO-2026-00012 | B13: ORD-504910 | C13: 46094 | D13: 46111 | E13: 46116 | F13: SUP-013 | G13: Casablanca | H13: Kenya | I13: Abuja Plant | J13: Electronics | K13: SKU-ELE-179 | L13: LED Driver | M13: 2943 | N13: KES | O13: =_xlfn.XLOOKUP(Supplier_Perf_Table[[#This Row],[Currency]],'Comments 2'!$C$4:$C$16,'Comments 2'!$D$4:$D$16) -> 0.0077 | P13: =IFERROR(Supplier_Perf_Table[[#This Row],[Unit_Cost]]*Supplier_Perf_Table[[#This Row],[Dollar Equivalent]],"") -> 22.6611 | Q13: 50 | R13: 147150 | S13: =Supplier_Perf_Table[[#This Row],[Unit_Cost]]*Supplier_Perf_Table[[#This Row],[Order_Quantity]] -> 147150 | T13: =IFERROR(Supplier_Perf_Table[[#This Row],[Dollar Equivalent]]*Supplier_Perf_Table[[#This Row],[Ordered_Value]],"") -> 1133.055 | U13: 0 | V13: 0 | W13: 22 | X13: =IFERROR(Supplier_Perf_Table[[#This Row],[Actual_Delivery_Date]]-Supplier_Perf_Table[[#This Row],[Order Date]],"") -> 22 | Y13: 17 | Z13: =IFERROR(Supplier_Perf_Table[[#This Row],[Expected Delivery_Date]]-Supplier_Perf_Table[[#This Row],[Order Date]],"") -> 17 | AA13: =Supplier_Perf_Table[[#This Row],[Calculated_Lead_Time2]]-Supplier_Perf_Table[[#This Row],[Calculated_Expected_Lead_Time]] -> 5 | AB13: 5 | AC13: Severely Delayed | AD13: Accepted | AE13: Missing Invoice | AF13: Net 30 | AG13: Courier | AH13: Kuehne+Nagel | AI13: fob | AJ13: N/A | AK13: 4.5 | AL13: API Feed | AM13: Late delivery; Invoice issue
A14: PO-2026-00013 | B14: ORD-105026 | C14: 46118 | D14: 46184 | E14: 46183 | F14: SUP-003 | G14: Sahara | H14: Nigeria | I14: Nairobi DC | J14: Raw Materials | K14: SKU-RAW-990 | L14: Chemical Additive | M14: 719.52 | N14: ZAR | O14: =_xlfn.XLOOKUP(Supplier_Perf_Table[[#This Row],[Currency]],'Comments 2'!$C$4:$C$16,'Comments 2'!$D$4:$D$16) -> 0.061 | P14: =IFERROR(Supplier_Perf_Table[[#This Row],[Unit_Cost]]*Supplier_Perf_Table[[#This Row],[Dollar Equivalent]],"") -> 43.89072 | Q14: 1000 | R14: 719520 | S14: =Supplier_Perf_Table[[#This Row],[Unit_Cost]]*Supplier_Perf_Table[[#This Row],[Order_Quantity]] -> 719520 | T14: =IFERROR(Supplier_Perf_Table[[#This Row],[Dollar Equivalent]]*Supplier_Perf_Table[[#This Row],[Ordered_Value]],"") -> 43890.72 | U14: 1 | V14: 0.001 | W14: 6 | X14: =IFERROR(Supplier_Perf_Table[[#This Row],[Actual_Delivery_Date]]-Supplier_Perf_Table[[#This Row],[Order Date]],"") -> 65 | Y14: 7 | Z14: =IFERROR(Supplier_Perf_Table[[#This Row],[Expected Delivery_Date]]-Supplier_Perf_Table[[#This Row],[Order Date]],"") -> 66 | AA14: =Supplier_Perf_Table[[#This Row],[Calculated_Lead_Time2]]-Supplier_Perf_Table[[#This Row],[Calculated_Expected_Lead_Time]] -> -1 | AC14: On Time | AD14: Accepted | AE14: Missing Invoice | AF14: Not Stated | AG14: Rail | AH14: Kuehne+Nagel | AI14: FOB | AJ14: N/A | AK14: 3.3 | AL14: ERP | AM14: Invoice issue
A15: PO-2026-00014 | B15: ORD-659835 | C15: 46165 | D15: 46172 | E15: 46173 | F15: SUP-003 | G15: Sahara | H15: Nigeria | I15: Accra Hub | J15: Raw Materials | K15: SKU-RAW-121 | L15: Chemical Additive | M15: 286.22 | N15: NGN | O15: =_xlfn.XLOOKUP(Supplier_Perf_Table[[#This Row],[Currency]],'Comments 2'!$C$4:$C$16,'Comments 2'!$D$4:$D$16) -> 0.00073 | P15: =IFERROR(Supplier_Perf_Table[[#This Row],[Unit_Cost]]*Supplier_Perf_Table[[#This Row],[Dollar Equivalent]],"") -> 0.2089406 | Q15: 150 | R15: 42933 | S15: =Supplier_Perf_Table[[#This Row],[Unit_Cost]]*Supplier_Perf_Table[[#This Row],[Order_Quantity]] -> 42933 | T15: =IFERROR(Supplier_Perf_Table[[#This Row],[Dollar Equivalent]]*Supplier_Perf_Table[[#This Row],[Ordered_Value]],"") -> 31.34109 | U15: 2 | V15: 0.0133 | W15: 8 | X15: =IFERROR(Supplier_Perf_Table[[#This Row],[Actual_Delivery_Date]]-Supplier_Perf_Table[[#This Row],[Order Date]],"") -> 8 | Y15: 7 | Z15: =IFERROR(Supplier_Perf_Table[[#This Row],[Expected Delivery_Date]]-Supplier_Perf_Table[[#This Row],[Order Date]],"") -> 7 | AA15: =Supplier_Perf_Table[[#This Row],[Calculated_Lead_Time2]]-Supplier_Perf_Table[[#This Row],[Calculated_Expected_Lead_Time]] -> 1 | AB15: 1 | AC15: Late | AD15: Accepted | AE15: Pending | AF15: Net 30 | AG15: Road | AH15: Bollore Logistics | AI15: FOB | AJ15: N/A | AK15: 4.2 | AL15: Manual Excel Upload | AM15: Late delivery
A16: PO-2026-00015 | B16: ORD-389548 | C16: 46195 | D16: 46197 | E16: 46199 | F16: SUP-001 | G16: Primesteel | H16: Nigeria | I16: Kigali Assembly | J16: Metals | K16: SKU-MET-232 | L16: Aluminium Sheet | M16: 997.52 | N16: GHS | O16: =_xlfn.XLOOKUP(Supplier_Perf_Table[[#This Row],[Currency]],'Comments 2'!$C$4:$C$16,'Comments 2'!$D$4:$D$16) -> 0.089 | P16: =IFERROR(Supplier_Perf_Table[[#This Row],[Unit_Cost]]*Supplier_Perf_Table[[#This Row],[Dollar Equivalent]],"") -> 88.77928 | Q16: 2000 | R16: 1995040 | S16: =Supplier_Perf_Table[[#This Row],[Unit_Cost]]*Supplier_Perf_Table[[#This Row],[Order_Quantity]] -> 1995040 | T16: =IFERROR(Supplier_Perf_Table[[#This Row],[Dollar Equivalent]]*Supplier_Perf_Table[[#This Row],[Ordered_Value]],"") -> 177558.56 | U16: 31 | V16: 0.0155 | W16: 4 | X16: =IFERROR(Supplier_Perf_Table[[#This Row],[Actual_Delivery_Date]]-Supplier_Perf_Table[[#This Row],[Order Date]],"") -> 4 | Y16: 2 | Z16: =IFERROR(Supplier_Perf_Table[[#This Row],[Expected Delivery_Date]]-Supplier_Perf_Table[[#This Row],[Order Date]],"") -> 2 | AA16: =Supplier_Perf_Table[[#This Row],[Calculated_Lead_Time2]]-Supplier_Perf_Table[[#This Row],[Calculated_Expected_Lead_Time]] -> 2 | AB16: 2 | AC16: Delayed | AD16: Accepted | AE16: Not Stated | AF16: COD | AG16: Sea | AH16: Kuehne+Nagel | AI16: N/A | AJ16: N/A | AK16: 4 | AL16: API Feed | AM16: Late delivery; Invoice issue
A17: PO-2026-00016 | B17: ORD-899022 | C17: 46159 | D17: 46177 | E17: 46183 | F17: SUP-013 | G17: Casablanca | H17: Morocco | I17: Dar es Salaam Port | J17: Metals | K17: SKU-MET-608 | L17: Steel Coil | M17: 1754.18 | N17: MAD | O17: =_xlfn.XLOOKUP(Supplier_Perf_Table[[#This Row],[Currency]],'Comments 2'!$C$4:$C$16,'Comments 2'!$D$4:$D$16) -> 0.11 | P17: =IFERROR(Supplier_Perf_Table[[#This Row],[Unit_Cost]]*Supplier_Perf_Table[[#This Row],[Dollar Equivalent]],"") -> 192.9598 | Q17: 200 | R17: 350836 | S17: =Supplier_Perf_Table[[#This Row],[Unit_Cost]]*Supplier_Perf_Table[[#This Row],[Order_Quantity]] -> 350836 | T17: =IFERROR(Supplier_Perf_Table[[#This Row],[Dollar Equivalent]]*Supplier_Perf_Table[[#This Row],[Ordered_Value]],"") -> 38591.96 | U17: 6 | V17: 0.03 | W17: 24 | X17: =IFERROR(Supplier_Perf_Table[[#This Row],[Actual_Delivery_Date]]-Supplier_Perf_Table[[#This Row],[Order Date]],"") -> 24 | Y17: 18 | Z17: =IFERROR(Supplier_Perf_Table[[#This Row],[Expected Delivery_Date]]-Supplier_Perf_Table[[#This Row],[Order Date]],"") -> 18 | AA17: =Supplier_Perf_Table[[#This Row],[Calculated_Lead_Time2]]-Supplier_Perf_Table[[#This Row],[Calculated_Expected_Lead_Time]] -> 6 | AB17: 6 | AC17: Severely Delayed | AD17: Accepted | AE17: Disputed | AF17: Net 45 | AG17: Road | AH17: Local Truck Partner | AI17: FOB | AJ17: N/A | AK17: 2.1 | AL17: API Feed | AM17: Late delivery; Invoice issue
A18: PO-2026-00017 | B18: ORD-683817 | C18: 46163 | D18: 46177 | E18: 46183 | F18: SUP-007 | G18: Dar | H18: Tanzania | I18: Port Harcourt Warehouse | J18: Machinery Parts | K18: SKU-MAC-888 | L18: Bearing Set | M18: 2499.94 | N18: GHS | O18: =_xlfn.XLOOKUP(Supplier_Perf_Table[[#This Row],[Currency]],'Comments 2'!$C$4:$C$16,'Comments 2'!$D$4:$D$16) -> 0.089 | P18: =IFERROR(Supplier_Perf_Table[[#This Row],[Unit_Cost]]*Supplier_Perf_Table[[#This Row],[Dollar Equivalent]],"") -> 222.49466 | Q18: 200 | R18: 499988 | S18: =Supplier_Perf_Table[[#This Row],[Unit_Cost]]*Supplier_Perf_Table[[#This Row],[Order_Quantity]] -> 499988 | T18: =IFERROR(Supplier_Perf_Table[[#This Row],[Dollar Equivalent]]*Supplier_Perf_Table[[#This Row],[Ordered_Value]],"") -> 44498.932 | U18: 5 | V18: 0.025 | W18: 20 | X18: =IFERROR(Supplier_Perf_Table[[#This Row],[Actual_Delivery_Date]]-Supplier_Perf_Table[[#This Row],[Order Date]],"") -> 20 | Y18: 14 | Z18: =IFERROR(Supplier_Perf_Table[[#This Row],[Expected Delivery_Date]]-Supplier_Perf_Table[[#This Row],[Order Date]],"") -> 14 | AA18: =Supplier_Perf_Table[[#This Row],[Calculated_Lead_Time2]]-Supplier_Perf_Table[[#This Row],[Calculated_Expected_Lead_Time]] -> 6 | AB18: 6 | AC18: Severely Delayed | AD18: Accepted | AE18: Matched | AF18: COD | AG18: Courier | AH18: Local Truck Partner | AI18: FOB | AJ18: N/A | AK18: 2.5 | AL18: API Feed | AM18: Late delivery
A19: PO-2026-00011 | B19: ORD-334714 | C19: 46079 | D19: 46091 | E19: 46092 | F19: SUP-015 | G19: Kampala | H19: Uganda | I19: Nairobi DC | J19: Machinery Parts | K19: SKU-MAC-913 | L19: Conveyor Belt | M19: 375.4 | N19: USD | O19: =_xlfn.XLOOKUP(Supplier_Perf_Table[[#This Row],[Currency]],'Comments 2'!$C$4:$C$16,'Comments 2'!$D$4:$D$16) -> 1 | P19: =IFERROR(Supplier_Perf_Table[[#This Row],[Unit_Cost]]*Supplier_Perf_Table[[#This Row],[Dollar Equivalent]],"") -> 375.4 | Q19: 200 | R19: 75080 | S19: =Supplier_Perf_Table[[#This Row],[Unit_Cost]]*Supplier_Perf_Table[[#This Row],[Order_Quantity]] -> 75080 | T19: =IFERROR(Supplier_Perf_Table[[#This Row],[Dollar Equivalent]]*Supplier_Perf_Table[[#This Row],[Ordered_Value]],"") -> 75080 | U19: 11 | V19: 0.055 | W19: 13 | X19: =IFERROR(Supplier_Perf_Table[[#This Row],[Actual_Delivery_Date]]-Supplier_Perf_Table[[#This Row],[Order Date]],"") -> 13 | Y19: 12 | Z19: =IFERROR(Supplier_Perf_Table[[#This Row],[Expected Delivery_Date]]-Supplier_Perf_Table[[#This Row],[Order Date]],"") -> 12 | AA19: =Supplier_Perf_Table[[#This Row],[Calculated_Lead_Time2]]-Supplier_Perf_Table[[#This Row],[Calculated_Expected_Lead_Time]] -> 1 | AB19: 1 | AC19: Late | AD19: Hold | AE19: Missing Invoice | AF19: Net 45 | AG19: Rail | AH19: No Carrier Listed | AI19: FOB | AJ19: Wrong specification | AK19: 1.5 | AL19: Warehouse Scan | AM19: Late delivery; Quality issue; Invoice issue
A20: PO-2026-00019 | B20: ORD-808592 | C20: 46045 | D20: 46056 | E20: 46057 | F20: SUP-002 | G20: Kentech | H20: Kenya | I20: Dar es Salaam Port | J20: Electronics | K20: SKU-ELE-297 | L20: Sensor Module | M20: 3315.83 | N20: USD | O20: =_xlfn.XLOOKUP(Supplier_Perf_Table[[#This Row],[Currency]],'Comments 2'!$C$4:$C$16,'Comments 2'!$D$4:$D$16) -> 1 | P20: =IFERROR(Supplier_Perf_Table[[#This Row],[Unit_Cost]]*Supplier_Perf_Table[[#This Row],[Dollar Equivalent]],"") -> 3315.83 | Q20: 50 | R20: 165791.5 | S20: =Supplier_Perf_Table[[#This Row],[Unit_Cost]]*Supplier_Perf_Table[[#This Row],[Order_Quantity]] -> 165791.5 | T20: =IFERROR(Supplier_Perf_Table[[#This Row],[Dollar Equivalent]]*Supplier_Perf_Table[[#This Row],[Ordered_Value]],"") -> 165791.5 | U20: 0 | V20: 0 | W20: 12 | X20: =IFERROR(Supplier_Perf_Table[[#This Row],[Actual_Delivery_Date]]-Supplier_Perf_Table[[#This Row],[Order Date]],"") -> 12 | Y20: 11 | Z20: =IFERROR(Supplier_Perf_Table[[#This Row],[Expected Delivery_Date]]-Supplier_Perf_Table[[#This Row],[Order Date]],"") -> 11 | AA20: =Supplier_Perf_Table[[#This Row],[Calculated_Lead_Time2]]-Supplier_Perf_Table[[#This Row],[Calculated_Expected_Lead_Time]] -> 1 | AB20: 1 | AC20: Late | AD20: Accepted | AE20: Pending | AF20: Advance | AG20: Not Stated | AH20: DHL | AI20: DAP | AJ20: N/A | AK20: 2.2 | AL20: Manual Excel Upload | AM20: Late delivery
A21: PO-2026-00020 | B21: ORD-406468 | C21: 46073 | D21: 46082 | E21: 46086 | F21: SUP-015 | G21: Kampala | H21: Uganda | I21: Lagos DC | J21: Machinery Parts | K21: SKU-MAC-761 | L21: Conveyor Belt | M21: 1685.89 | N21: KES | O21: =_xlfn.XLOOKUP(Supplier_Perf_Table[[#This Row],[Currency]],'Comments 2'!$C$4:$C$16,'Comments 2'!$D$4:$D$16) -> 0.0077 | P21: =IFERROR(Supplier_Perf_Table[[#This Row],[Unit_Cost]]*Supplier_Perf_Table[[#This Row],[Dollar Equivalent]],"") -> 12.981353 | Q21: 750 | R21: 1264417.5 | S21: =Supplier_Perf_Table[[#This Row],[Unit_Cost]]*Supplier_Perf_Table[[#This Row],[Order_Quantity]] -> 1264417.5 | T21: =IFERROR(Supplier_Perf_Table[[#This Row],[Dollar Equivalent]]*Supplier_Perf_Table[[#This Row],[Ordered_Value]],"") -> 9736.0148 | U21: 17 | V21: 0.0227 | W21: 13 | X21: =IFERROR(Supplier_Perf_Table[[#This Row],[Actual_Delivery_Date]]-Supplier_Perf_Table[[#This Row],[Order Date]],"") -> 13 | Y21: 9 | Z21: =IFERROR(Supplier_Perf_Table[[#This Row],[Expected Delivery_Date]]-Supplier_Perf_Table[[#This Row],[Order Date]],"") -> 9 | AA21: =Supplier_Perf_Table[[#This Row],[Calculated_Lead_Time2]]-Supplier_Perf_Table[[#This Row],[Calculated_Expected_Lead_Time]] -> 4 | AB21: 4 | AC21: Severely Delayed | AD21: Accepted | AE21: Disputed | AF21: Net 30 | AG21: Sea | AH21: DHL | AI21: fob | AJ21: N/A | AK21: 4.8 | AL21: Legacy CSV | AM21: Missing/invalid supplier ID; Late delivery; Invoice issue
A22: PO-2026-00021 | B22: ORD-968088 | C22: 46095 | D22: 46107 | E22: 46099 | F22: SUP-015 | G22: Kampala | H22: Uganda | I22: Nairobi DC | J22: Machinery Parts | K22: SKU-MAC-781 | L22: Gear Assembly | M22: 1181.69 | N22: EGP | O22: =_xlfn.XLOOKUP(Supplier_Perf_Table[[#This Row],[Currency]],'Comments 2'!$C$4:$C$16,'Comments 2'!$D$4:$D$16) -> 0.019 | P22: =IFERROR(Supplier_Perf_Table[[#This Row],[Unit_Cost]]*Supplier_Perf_Table[[#This Row],[Dollar Equivalent]],"") -> 22.45211 | Q22: 500 | R22: 590845 | S22: =Supplier_Perf_Table[[#This Row],[Unit_Cost]]*Supplier_Perf_Table[[#This Row],[Order_Quantity]] -> 590845 | T22: =IFERROR(Supplier_Perf_Table[[#This Row],[Dollar Equivalent]]*Supplier_Perf_Table[[#This Row],[Ordered_Value]],"") -> 11226.055 | U22: 6 | V22: 0.012 | W22: 4 | X22: =IFERROR(Supplier_Perf_Table[[#This Row],[Actual_Delivery_Date]]-Supplier_Perf_Table[[#This Row],[Order Date]],"") -> 4 | Y22: 12 | Z22: =IFERROR(Supplier_Perf_Table[[#This Row],[Expected Delivery_Date]]-Supplier_Perf_Table[[#This Row],[Order Date]],"") -> 12 | AA22: =Supplier_Perf_Table[[#This Row],[Calculated_Lead_Time2]]-Supplier_Perf_Table[[#This Row],[Calculated_Expected_Lead_Time]] -> -8 | AB22: -8 | AC22: On Time | AD22: Accepted | AE22: Matched | AF22: Not Stated | AG22: Air | AH22: Maersk | AI22: N/A | AJ22: N/A | AK22: 2.9 | AL22: Manual Excel Upload | AM22: N/A
A23: PO-2026-00022 | B23: ORD-964937 | C23: 46111 | D23: 46125 | E23: 46137 | F23: SUP-002 | G23: Kentech | H23: Kenya | I23: Abuja Plant | J23: Raw Materials | K23: SKU-RAW-926 | L23: Polymer Resin | N23: KES | O23: =_xlfn.XLOOKUP(Supplier_Perf_Table[[#This Row],[Currency]],'Comments 2'!$C$4:$C$16,'Comments 2'!$D$4:$D$16) -> 0.0077 | P23: =IFERROR(Supplier_Perf_Table[[#This Row],[Unit_Cost]]*Supplier_Perf_Table[[#This Row],[Dollar Equivalent]],"") | Q23: 750 | R23: 359227.5 | S23: =Supplier_Perf_Table[[#This Row],[Unit_Cost]]*Supplier_Perf_Table[[#This Row],[Order_Quantity]] -> #VALUE! | T23: =IFERROR(Supplier_Perf_Table[[#This Row],[Dollar Equivalent]]*Supplier_Perf_Table[[#This Row],[Ordered_Value]],"") -> 2766.0518 | V23: 0 | W23: 26 | X23: =IFERROR(Supplier_Perf_Table[[#This Row],[Actual_Delivery_Date]]-Supplier_Perf_Table[[#This Row],[Order Date]],"") -> 26 | Y23: 14 | Z23: =IFERROR(Supplier_Perf_Table[[#This Row],[Expected Delivery_Date]]-Supplier_Perf_Table[[#This Row],[Order Date]],"") -> 14 | AA23: =Supplier_Perf_Table[[#This Row],[Calculated_Lead_Time2]]-Supplier_Perf_Table[[#This Row],[Calculated_Expected_Lead_Time]] -> 12 | AB23: 12 | AC23: Very Late | AD23: Accepted | AE23: Matched | AF23: Net 30 | AG23: Rail | AH23: GIG Logistics | AI23: DAP | AJ23: N/A | AK23: 1.6 | AL23: Manual Excel Upload | AM23: Late delivery
A24: PO-2026-00023 | B24: ORD-282581 | C24: 46082 | D24: 46093 | E24: 46104 | F24: SUP-006 | G24: AccraAI | H24: Ghana | I24: Dar es Salaam Port | J24: Raw Materials | K24: SKU-RAW-494 | L24: Chemical Additive | M24: 194.64 | N24: GHS | O24: =_xlfn.XLOOKUP(Supplier_Perf_Table[[#This Row],[Currency]],'Comments 2'!$C$4:$C$16,'Comments 2'!$D$4:$D$16) -> 0.089 | P24: =IFERROR(Supplier_Perf_Table[[#This Row],[Unit_Cost]]*Supplier_Perf_Table[[#This Row],[Dollar Equivalent]],"") -> 17.32296 | Q24: 150 | R24: 29196 | S24: =Supplier_Perf_Table[[#This Row],[Unit_Cost]]*Supplier_Perf_Table[[#This Row],[Order_Quantity]] -> 29196 | T24: =IFERROR(Supplier_Perf_Table[[#This Row],[Dollar Equivalent]]*Supplier_Perf_Table[[#This Row],[Ordered_Value]],"") -> 2598.444 | U24: 2 | V24: 0.0133 | W24: 22 | X24: =IFERROR(Supplier_Perf_Table[[#This Row],[Actual_Delivery_Date]]-Supplier_Perf_Table[[#This Row],[Order Date]],"") -> 22 | Y24: 11 | Z24: =IFERROR(Supplier_Perf_Table[[#This Row],[Expected Delivery_Date]]-Supplier_Perf_Table[[#This Row],[Order Date]],"") -> 11 | AA24: =Supplier_Perf_Table[[#This Row],[Calculated_Lead_Time2]]-Supplier_Perf_Table[[#This Row],[Calculated_Expected_Lead_Time]] -> 11 | AB24: 11 | AC24: Late | AD24: Accepted | AE24: Not Stated | AF24: 50% Advance / 50% Delivery | AG24: Sea | AH24: No Carrier Listed | AI24: FOB | AJ24: N/A | AK24: 3 | AL24: Email Invoice | AM24: Late delivery; Invoice issue
A25: PO-2026-00024 | B25: ORD-661755 | C25: 46067 | D25: 46070 | E25: 46075 | F25: SUP-008 | G25: LagosPR | H25: Nigeria | I25: Lagos DC | J25: Packaging | K25: SKU-PAC-793 | L25: Shipping Carton | M25: 439.15 | N25: GHS | O25: =_xlfn.XLOOKUP(Supplier_Perf_Table[[#This Row],[Currency]],'Comments 2'!$C$4:$C$16,'Comments 2'!$D$4:$D$16) -> 0.089 | P25: =IFERROR(Supplier_Perf_Table[[#This Row],[Unit_Cost]]*Supplier_Perf_Table[[#This Row],[Dollar Equivalent]],"") -> 39.08435 | Q25: 1500 | R25: 658725 | S25: =Supplier_Perf_Table[[#This Row],[Unit_Cost]]*Supplier_Perf_Table[[#This Row],[Order_Quantity]] -> 658725 | T25: =IFERROR(Supplier_Perf_Table[[#This Row],[Dollar Equivalent]]*Supplier_Perf_Table[[#This Row],[Ordered_Value]],"") -> 58626.525 | U25: 15 | V25: 0.01 | W25: 8 | X25: =IFERROR(Supplier_Perf_Table[[#This Row],[Actual_Delivery_Date]]-Supplier_Perf_Table[[#This Row],[Order Date]],"") -> 8 | Y25: 3 | Z25: =IFERROR(Supplier_Perf_Table[[#This Row],[Expected Delivery_Date]]-Supplier_Perf_Table[[#This Row],[Order Date]],"") -> 3 | AA25: =Supplier_Perf_Table[[#This Row],[Calculated_Lead_Time2]]-Supplier_Perf_Table[[#This Row],[Calculated_Expected_Lead_Time]] -> 5 | AB25: 5 | AC25: Very Late | AD25: Accepted | AE25: Not Stated | AF25: COD | AG25: Not Stated | AH25: Kuehne+Nagel | AI25: N/A | AJ25: N/A | AK25: 2.7 | AL25: Email Invoice | AM25: Late delivery; Invoice issue
A26: PO-2026-00025 | B26: ORD-993058 | C26: 46141 | D26: 46155 | E26: 46163 | F26: SUP-005 | G26: Cape | H26: South Africa | I26: Dar es Salaam Port | J26: Industrial Supplies | K26: SKU-IND-272 | L26: Filter Cartridge | M26: 747.31 | N26: NGN | O26: =_xlfn.XLOOKUP(Supplier_Perf_Table[[#This Row],[Currency]],'Comments 2'!$C$4:$C$16,'Comments 2'!$D$4:$D$16) -> 0.00073 | P26: =IFERROR(Supplier_Perf_Table[[#This Row],[Unit_Cost]]*Supplier_Perf_Table[[#This Row],[Dollar Equivalent]],"") -> 0.5455363 | Q26: 1000 | R26: 747310 | S26: =Supplier_Perf_Table[[#This Row],[Unit_Cost]]*Supplier_Perf_Table[[#This Row],[Order_Quantity]] -> 747310 | T26: =IFERROR(Supplier_Perf_Table[[#This Row],[Dollar Equivalent]]*Supplier_Perf_Table[[#This Row],[Ordered_Value]],"") -> 545.5363 | U26: 14 | V26: 0.014 | W26: 22 | X26: =IFERROR(Supplier_Perf_Table[[#This Row],[Actual_Delivery_Date]]-Supplier_Perf_Table[[#This Row],[Order Date]],"") -> 22 | Y26: 14 | Z26: =IFERROR(Supplier_Perf_Table[[#This Row],[Expected Delivery_Date]]-Supplier_Perf_Table[[#This Row],[Order Date]],"") -> 14 | AA26: =Supplier_Perf_Table[[#This Row],[Calculated_Lead_Time2]]-Supplier_Perf_Table[[#This Row],[Calculated_Expected_Lead_Time]] -> 8 | AB26: 8 | AC26: Very Late | AD26: Accepted | AE26: Matched | AF26: Advance | AG26: Rail | AH26: Local Truck Partner | AI26: N/A | AJ26: N/A | AK26: 2.9 | AL26: Warehouse Scan | AM26: Late delivery
A27: PO-2026-00026 | B27: ORD-554955 | C27: 46049 | D27: 46068 | E27: 46073 | F27: SUP-005 | G27: Cape | H27: South Africa | I27: Accra Hub | J27: Industrial Supplies | K27: SKU-IND-780 | L27: Welding Rod | M27: 765.07 | N27: KES | O27: =_xlfn.XLOOKUP(Supplier_Perf_Table[[#This Row],[Currency]],'Comments 2'!$C$4:$C$16,'Comments 2'!$D$4:$D$16) -> 0.0077 | P27: =IFERROR(Supplier_Perf_Table[[#This Row],[Unit_Cost]]*Supplier_Perf_Table[[#This Row],[Dollar Equivalent]],"") -> 5.891039 | Q27: 500 | R27: 382535 | S27: =Supplier_Perf_Table[[#This Row],[Unit_Cost]]*Supplier_Perf_Table[[#This Row],[Order_Quantity]] -> 382535 | T27: =IFERROR(Supplier_Perf_Table[[#This Row],[Dollar Equivalent]]*Supplier_Perf_Table[[#This Row],[Ordered_Value]],"") -> 2945.5195 | U27: 6 | V27: 0.012 | W27: 24 | X27: =IFERROR(Supplier_Perf_Table[[#This Row],[Actual_Delivery_Date]]-Supplier_Perf_Table[[#This Row],[Order Date]],"") -> 24 | Y27: 19 | Z27: =IFERROR(Supplier_Perf_Table[[#This Row],[Expected Delivery_Date]]-Supplier_Perf_Table[[#This Row],[Order Date]],"") -> 19 | AA27: =Supplier_Perf_Table[[#This Row],[Calculated_Lead_Time2]]-Supplier_Perf_Table[[#This Row],[Calculated_Expected_Lead_Time]] -> 5 | AB27: 5 | AC27: Late | AD27: Accepted | AE27: Matched | AF27: Not Stated | AG27: Not Stated | AH27: DHL | AI27: DDP | AJ27: N/A | AK27: 2.4 | AL27: ERP | AM27: Late delivery
A28: PO-2026-00027 | B28: ORD-922995 | C28: 46117 | D28: 46126 | E28: 46128 | F28: SUP-008 | G28: LagosPR | H28: Nigeria | I28: Dar es Salaam Port | J28: Packaging | K28: SKU-PAC-247 | L28: Plastic Film Roll | M28: 601.06 | N28: ZAR | O28: =_xlfn.XLOOKUP(Supplier_Perf_Table[[#This Row],[Currency]],'Comments 2'!$C$4:$C$16,'Comments 2'!$D$4:$D$16) -> 0.061 | P28: =IFERROR(Supplier_Perf_Table[[#This Row],[Unit_Cost]]*Supplier_Perf_Table[[#This Row],[Dollar Equivalent]],"") -> 36.66466 | Q28: 100 | R28: 60106 | S28: =Supplier_Perf_Table[[#This Row],[Unit_Cost]]*Supplier_Perf_Table[[#This Row],[Order_Quantity]] -> 60106 | T28: =IFERROR(Supplier_Perf_Table[[#This Row],[Dollar Equivalent]]*Supplier_Perf_Table[[#This Row],[Ordered_Value]],"") -> 3666.466 | U28: 2 | V28: 0.02 | W28: 11 | X28: =IFERROR(Supplier_Perf_Table[[#This Row],[Actual_Delivery_Date]]-Supplier_Perf_Table[[#This Row],[Order Date]],"") -> 11 | Y28: 9 | Z28: =IFERROR(Supplier_Perf_Table[[#This Row],[Expected Delivery_Date]]-Supplier_Perf_Table[[#This Row],[Order Date]],"") -> 9 | AA28: =Supplier_Perf_Table[[#This Row],[Calculated_Lead_Time2]]-Supplier_Perf_Table[[#This Row],[Calculated_Expected_Lead_Time]] -> 2 | AB28: 2 | AC28: Delayed | AD28: Accepted | AE28: Pending | AF28: Not Stated | AG28: Air | AH28: Maersk | AI28: DAP | AJ28: N/A | AK28: 4.7 | AL28: Supplier Portal | AM28: Late delivery
A29: PO-2026-00028 | B29: ORD-247297 | C29: 46166 | D29: 46184 | E29: 46173 | F29: SUP-009 | G29: Mombasa | H29: Kenya | I29: Nairobi DC | J29: Electronics | K29: SKU-ELE-420 | L29: Power Adapter | M29: 719.17 | N29: USD | O29: =_xlfn.XLOOKUP(Supplier_Perf_Table[[#This Row],[Currency]],'Comments 2'!$C$4:$C$16,'Comments 2'!$D$4:$D$16) -> 1 | P29: =IFERROR(Supplier_Perf_Table[[#This Row],[Unit_Cost]]*Supplier_Perf_Table[[#This Row],[Dollar Equivalent]],"") -> 719.17 | Q29: 500 | R29: 359585 | S29: =Supplier_Perf_Table[[#This Row],[Unit_Cost]]*Supplier_Perf_Table[[#This Row],[Order_Quantity]] -> 359585 | T29: =IFERROR(Supplier_Perf_Table[[#This Row],[Dollar Equivalent]]*Supplier_Perf_Table[[#This Row],[Ordered_Value]],"") -> 359585 | U29: 2 | V29: 0.004 | W29: 7 | X29: =IFERROR(Supplier_Perf_Table[[#This Row],[Actual_Delivery_Date]]-Supplier_Perf_Table[[#This Row],[Order Date]],"") -> 7 | Z29: =IFERROR(Supplier_Perf_Table[[#This Row],[Expected Delivery_Date]]-Supplier_Perf_Table[[#This Row],[Order Date]],"") -> 18 | AA29: =Supplier_Perf_Table[[#This Row],[Calculated_Lead_Time2]]-Supplier_Perf_Table[[#This Row],[Calculated_Expected_Lead_Time]] -> -11 | AB29: -11 | AC29: On Time | AD29: Accepted | AE29: Pending | AF29: COD | AG29: Road | AH29: Maersk | AI29: DDP | AJ29: N/A | AK29: 3.6 | AL29: Legacy CSV | AM29: N/A
A30: PO-2026-00009 | B30: ORD-302588 | C30: 46128 | D30: 46138 | E30: 46141 | F30: SUP-010 | G30: AddisFW | H30: Ethiopia | I30: Accra Hub | J30: Textiles | K30: SKU-TEX-685 | L30: Label Tape | M30: 230.96 | N30: NGN | O30: =_xlfn.XLOOKUP(Supplier_Perf_Table[[#This Row],[Currency]],'Comments 2'!$C$4:$C$16,'Comments 2'!$D$4:$D$16) -> 0.00073 | P30: =IFERROR(Supplier_Perf_Table[[#This Row],[Unit_Cost]]*Supplier_Perf_Table[[#This Row],[Dollar Equivalent]],"") -> 0.1686008 | Q30: 750 | R30: 173220 | S30: =Supplier_Perf_Table[[#This Row],[Unit_Cost]]*Supplier_Perf_Table[[#This Row],[Order_Quantity]] -> 173220 | T30: =IFERROR(Supplier_Perf_Table[[#This Row],[Dollar Equivalent]]*Supplier_Perf_Table[[#This Row],[Ordered_Value]],"") -> 126.4506 | U30: 17 | V30: 0.0227 | W30: 13 | X30: =IFERROR(Supplier_Perf_Table[[#This Row],[Actual_Delivery_Date]]-Supplier_Perf_Table[[#This Row],[Order Date]],"") -> 13 | Y30: 10 | Z30: =IFERROR(Supplier_Perf_Table[[#This Row],[Expected Delivery_Date]]-Supplier_Perf_Table[[#This Row],[Order Date]],"") -> 10 | AA30: =Supplier_Perf_Table[[#This Row],[Calculated_Lead_Time2]]-Supplier_Perf_Table[[#This Row],[Calculated_Expected_Lead_Time]] -> 3 | AB30: 3 | AC30: Late | AD30: Accepted | AE30: Matched | AF30: Net 30 | AG30: Sea | AH30: DHL | AI30: FOB | AJ30: N/A | AK30: 3.9 | AL30: Email Invoice | AM30: Late delivery
A31: PO-2026-00030 | B31: ORD-155259 | C31: 46078 | D31: 46090 | E31: 46086 | F31: SUP-014 | G31: Kano | H31: Nigeria | I31: Cape Town Plant | J31: Industrial Supplies | K31: SKU-IND-332 | L31: Lubricant Drum | M31: 606.01 | N31: EGP | O31: =_xlfn.XLOOKUP(Supplier_Perf_Table[[#This Row],[Currency]],'Comments 2'!$C$4:$C$16,'Comments 2'!$D$4:$D$16) -> 0.019 | P31: =IFERROR(Supplier_Perf_Table[[#This Row],[Unit_Cost]]*Supplier_Perf_Table[[#This Row],[Dollar Equivalent]],"") -> 11.51419 | Q31: 75 | R31: 45450.75 | S31: =Supplier_Perf_Table[[#This Row],[Unit_Cost]]*Supplier_Perf_Table[[#This Row],[Order_Quantity]] -> 45450.75 | T31: =IFERROR(Supplier_Perf_Table[[#This Row],[Dollar Equivalent]]*Supplier_Perf_Table[[#This Row],[Ordered_Value]],"") -> 863.56425 | U31: 0 | V31: 0 | W31: 8 | X31: =IFERROR(Supplier_Perf_Table[[#This Row],[Actual_Delivery_Date]]-Supplier_Perf_Table[[#This Row],[Order Date]],"") -> 8 | Y31: 12 | Z31: =IFERROR(Supplier_Perf_Table[[#This Row],[Expected Delivery_Date]]-Supplier_Perf_Table[[#This Row],[Order Date]],"") -> 12 | AA31: =Supplier_Perf_Table[[#This Row],[Calculated_Lead_Time2]]-Supplier_Perf_Table[[#This Row],[Calculated_Expected_Lead_Time]] -> -4 | AB31: -4 | AC31: On Time | AD31: Accepted | AE31: Matched | AF31: Advance | AG31: Road | AH31: DHL | AI31: fob | AJ31: N/A | AK31: 3.9 | AL31: API Feed | AM31: N/A
A32: PO-2026-00020 | B32: ORD-478850 | C32: 46134 | D32: 46141 | E32: 46134 | F32: SUP-003 | G32: Sahara | H32: Nigeria | I32: Abuja Plant | J32: Packaging | K32: SKU-PAC-433 | L32: Bottle Caps | M32: 604.62 | N32: ZAR | O32: =_xlfn.XLOOKUP(Supplier_Perf_Table[[#This Row],[Currency]],'Comments 2'!$C$4:$C$16,'Comments 2'!$D$4:$D$16) -> 0.061 | P32: =IFERROR(Supplier_Perf_Table[[#This Row],[Unit_Cost]]*Supplier_Perf_Table[[#This Row],[Dollar Equivalent]],"") -> 36.88182 | Q32: 2000 | R32: 1209240 | S32: =Supplier_Perf_Table[[#This Row],[Unit_Cost]]*Supplier_Perf_Table[[#This Row],[Order_Quantity]] -> 1209240 | T32: =IFERROR(Supplier_Perf_Table[[#This Row],[Dollar Equivalent]]*Supplier_Perf_Table[[#This Row],[Ordered_Value]],"") -> 73763.64 | U32: 26 | V32: 0.013 | W32: 0 | X32: =IFERROR(Supplier_Perf_Table[[#This Row],[Actual_Delivery_Date]]-Supplier_Perf_Table[[#This Row],[Order Date]],"") -> 0 | Y32: 7 | Z32: =IFERROR(Supplier_Perf_Table[[#This Row],[Expected Delivery_Date]]-Supplier_Perf_Table[[#This Row],[Order Date]],"") -> 7 | AA32: =Supplier_Perf_Table[[#This Row],[Calculated_Lead_Time2]]-Supplier_Perf_Table[[#This Row],[Calculated_Expected_Lead_Time]] -> -7 | AB32: -7 | AC32: On Time | AD32: Accepted | AE32: Disputed | AF32: Not Stated | AG32: Sea | AH32: Maersk | AI32: FOB | AJ32: N/A | AK32: 2.5 | AL32: Legacy CSV | AM32: Invoice issue
A33: PO-2026-00032 | B33: ORD-442501 | C33: 46187 | D33: 46198 | E33: 46200 | F33: SUP-010 | G33: AddisFW | H33: Ethiopia | I33: Cape Town Plant | J33: Raw Materials | K33: SKU-RAW-691 | L33: Polymer Resin | M33: 139.41 | N33: NGN | O33: =_xlfn.XLOOKUP(Supplier_Perf_Table[[#This Row],[Currency]],'Comments 2'!$C$4:$C$16,'Comments 2'!$D$4:$D$16) -> 0.00073 | P33: =IFERROR(Supplier_Perf_Table[[#This Row],[Unit_Cost]]*Supplier_Perf_Table[[#This Row],[Dollar Equivalent]],"") -> 0.1017693 | Q33: 75 | R33: 10455.75 | S33: =Supplier_Perf_Table[[#This Row],[Unit_Cost]]*Supplier_Perf_Table[[#This Row],[Order_Quantity]] -> 10455.75 | T33: =IFERROR(Supplier_Perf_Table[[#This Row],[Dollar Equivalent]]*Supplier_Perf_Table[[#This Row],[Ordered_Value]],"") -> 7.6326975 | U33: 0 | V33: 0 | W33: 13 | X33: =IFERROR(Supplier_Perf_Table[[#This Row],[Actual_Delivery_Date]]-Supplier_Perf_Table[[#This Row],[Order Date]],"") -> 13 | Y33: 11 | Z33: =IFERROR(Supplier_Perf_Table[[#This Row],[Expected Delivery_Date]]-Supplier_Perf_Table[[#This Row],[Order Date]],"") -> 11 | AA33: =Supplier_Perf_Table[[#This Row],[Calculated_Lead_Time2]]-Supplier_Perf_Table[[#This Row],[Calculated_Expected_Lead_Time]] -> 2 | AB33: 2 | AC33: Late | AD33: Accepted | AE33: Matched | AF33: Net 45 | AG33: Rail | AH33: No Carrier Listed | AI33: FOB | AJ33: N/A | AK33: 2.5 | AL33: Supplier Portal | AM33: Late delivery
A34: PO-2026-00033 | B34: ORD-614551 | C34: 46023 | D34: 46027 | E34: 46046 | F34: SUP-001 | G34: Primesteel | H34: Nigeria | I34: Kampala Warehouse | J34: Metals | K34: SKU-MET-325 | L34: Rebar Bundle | M34: 1980.29 | N34: ZAR | O34: =_xlfn.XLOOKUP(Supplier_Perf_Table[[#This Row],[Currency]],'Comments 2'!$C$4:$C$16,'Comments 2'!$D$4:$D$16) -> 0.061 | P34: =IFERROR(Supplier_Perf_Table[[#This Row],[Unit_Cost]]*Supplier_Perf_Table[[#This Row],[Dollar Equivalent]],"") -> 120.79769 | Q34: 150 | R34: 297043.5 | S34: =Supplier_Perf_Table[[#This Row],[Unit_Cost]]*Supplier_Perf_Table[[#This Row],[Order_Quantity]] -> 297043.5 | T34: =IFERROR(Supplier_Perf_Table[[#This Row],[Dollar Equivalent]]*Supplier_Perf_Table[[#This Row],[Ordered_Value]],"") -> 18119.654 | U34: 0 | V34: 0 | W34: 23 | X34: =IFERROR(Supplier_Perf_Table[[#This Row],[Actual_Delivery_Date]]-Supplier_Perf_Table[[#This Row],[Order Date]],"") -> 23 | Y34: 4 | Z34: =IFERROR(Supplier_Perf_Table[[#This Row],[Expected Delivery_Date]]-Supplier_Perf_Table[[#This Row],[Order Date]],"") -> 4 | AA34: =Supplier_Perf_Table[[#This Row],[Calculated_Lead_Time2]]-Supplier_Perf_Table[[#This Row],[Calculated_Expected_Lead_Time]] -> 19 | AB34: 19 | AC34: Late | AD34: Accepted | AE34: Matched | AF34: COD | AG34: Sea | AH34: GIG Logistics | AI34: FOB | AJ34: N/A | AK34: 2.9 | AL34: Email Invoice | AM34: Late delivery
